Workbook
Name UPDATE: 'Data Sheet'!$E$1
Name UPDATE: '[1]Data Sheet'!$E$1
Name UPDATE: #REF!

Sheet Intrinsic Growth
B3: Calculation Of ROIC | G3: ='Data Sheet'!F16 -> 43921 | H3: ='Data Sheet'!G16 -> 44286 | I3: ='Data Sheet'!H16 -> 44651 | J3: ='Data Sheet'!I16 -> 45016 | K3: ='Data Sheet'!J16 -> 45382 | L3: ='Data Sheet'!K16 -> 45747
B5: Current Asset
B6: ='Raw Data'!B34 -> Inventories | G6: ='Raw Data'!G34 -> 2767 | H6: ='Raw Data'!H34 -> 3579 | I6: ='Raw Data'!I34 -> 4096 | J6: ='Raw Data'!J34 -> 4251 | K6: ='Raw Data'!K34 -> 4022 | L6: ='Raw Data'!L34 -> 4415
B7: ='Raw Data'!B35 -> Trade receivables - | G7: ='Raw Data'!G35 -> 1149 | H7: ='Raw Data'!H35 -> 1758 | I7: ='Raw Data'!I35 -> 2236 | J7: ='Raw Data'!J35 -> 3079 | K7: ='Raw Data'!K35 -> 2997 | L7: ='Raw Data'!L35 -> 3819
B8: ='Raw Data'!B40 -> Loans n Advances | G8: ='Raw Data'!G40 -> 19 | H8: ='Raw Data'!H40 -> 78 | I8: ='Raw Data'!I40 -> 170 | J8: ='Raw Data'!J40 -> 188 | K8: ='Raw Data'!K40 -> 172 | L8: ='Raw Data'!L40 -> 242
B9: ='Raw Data'!B41 -> Other asset items | G9: ='Raw Data'!G41 -> 3774 | H9: ='Raw Data'!H41 -> 3957 | I9: ='Raw Data'!I41 -> 3851 | J9: ='Raw Data'!J41 -> 4189 | K9: ='Raw Data'!K41 -> 4345 | L9: ='Raw Data'!L41 -> 4679
B10: Total Current Assets | G10: =SUM(G6:G9) -> 7709 | H10: =SUM(H6:H9) -> 9372 | I10: =SUM(I6:I9) -> 10353 | J10: =SUM(J6:J9) -> 11707 | K10: =SUM(K6:K9) -> 11536 | L10: =SUM(L6:L9) -> 13155
B12: Current Liabilities
B13: ='Raw Data'!B11 -> Trade Payables | G13: ='Raw Data'!G49 -> -241 | H13: ='Raw Data'!H49 -> 1143 | I13: ='Raw Data'!I49 -> 644 | J13: ='Raw Data'!J49 -> -539 | K13: ='Raw Data'!K49 -> 269 | L13: ='Raw Data'!L49 -> 269
B14: ='Raw Data'!B12 -> Advance from Customers | G14: ='Raw Data'!G12 -> 158 | H14: ='Raw Data'!H12 -> 96 | I14: ='Raw Data'!I12 -> 119 | J14: ='Raw Data'!J12 -> 98 | K14: ='Raw Data'!K12 -> 91 | L14: ='Raw Data'!L12 -> 105
B15: ='Raw Data'!B13 -> Other liability items | G15: ='Raw Data'!G13 -> 4214 | H15: ='Raw Data'!H13 -> 12148 | I15: ='Raw Data'!I13 -> 11189 | J15: ='Raw Data'!J13 -> 11664 | K15: ='Raw Data'!K13 -> 15005 | L15: ='Raw Data'!L13 -> 17186
B16: Total Current Liabilities | G16: =SUM(G13:G15) -> 4131 | H16: =SUM(H13:H15) -> 13387 | I16: =SUM(I13:I15) -> 11952 | J16: =SUM(J13:J15) -> 11223 | K16: =SUM(K13:K15) -> 15365 | L16: =SUM(L13:L15) -> 17560
A18: # | B18: Net Working Capital | G18: =G10-G16 -> 3578 | H18: =H10-H16 -> -4015 | I18: =I10-I16 -> -1599 | J18: =J10-J16 -> 484 | K18: =K10-K16 -> -3829 | L18: =L10-L16 -> -4405
B20: Non-Current Assets
B21: ='Raw Data'!B17 -> Land | G21: ='Raw Data'!G17 -> 59 | H21: ='Raw Data'!H17 -> 477 | I21: ='Raw Data'!I17 -> 477 | J21: ='Raw Data'!J17 -> 609 | K21: ='Raw Data'!K17 -> 633 | L21: ='Raw Data'!L17 -> 628
B22: ='Raw Data'!B18 -> Building | G22: ='Raw Data'!G18 -> 2044 | H22: ='Raw Data'!H18 -> 2602 | I22: ='Raw Data'!I18 -> 2788 | J22: ='Raw Data'!J18 -> 3101 | K22: ='Raw Data'!K18 -> 3590 | L22: ='Raw Data'!L18 -> 3833
B23: ='Raw Data'!B19 -> Plant Machinery | G23: ='Raw Data'!G19 -> 5001 | H23: ='Raw Data'!H19 -> 6097 | I23: ='Raw Data'!I19 -> 6566 | J23: ='Raw Data'!J19 -> 7612 | K23: ='Raw Data'!K19 -> 8946 | L23: ='Raw Data'!L19 -> 9900
B24: ='Raw Data'!B20 -> Equipments | G24: ='Raw Data'!G20 -> 139 | H24: ='Raw Data'!H20 -> 175 | I24: ='Raw Data'!I20 -> 181 | J24: ='Raw Data'!J20 -> 185 | K24: ='Raw Data'!K20 -> 206 | L24: ='Raw Data'!L20 -> 245
B25: ='Raw Data'!B21 -> Furniture n fittings | G25: ='Raw Data'!G21 -> 154 | H25: ='Raw Data'!H21 -> 156 | I25: ='Raw Data'!I21 -> 152 | J25: ='Raw Data'!J21 -> 161 | K25: ='Raw Data'!K21 -> 165 | L25: ='Raw Data'!L21 -> 174
B26: ='Raw Data'!B23 -> Vehicles | G26: ='Raw Data'!G22 -> 0 | H26: ='Raw Data'!H22 -> 0 | I26: ='Raw Data'!I22 -> 0 | J26: ='Raw Data'!J22 -> 0 | K26: ='Raw Data'!K22 -> 0 | L26: ='Raw Data'!L22 -> 0
B27: ='Raw Data'!B24 -> Intangible Assets | G27: ='Raw Data'!G23 -> 0 | H27: ='Raw Data'!H23 -> 0 | I27: ='Raw Data'!I23 -> 0 | J27: ='Raw Data'!J23 -> 0 | K27: ='Raw Data'!K23 -> 0 | L27: ='Raw Data'!L23 -> 0
B28: ='Raw Data'!B25 -> Other fixed assets | G28: ='Raw Data'!G24 -> 0 | H28: ='Raw Data'!H24 -> 0 | I28: ='Raw Data'!I24 -> 0 | J28: ='Raw Data'!J24 -> 33 | K28: ='Raw Data'!K24 -> 39 | L28: ='Raw Data'!L24 -> 102
B30: Gross Block | G30: =SUM(G21:G29) -> 7397 | H30: =SUM(H21:H29) -> 9507 | I30: =SUM(I21:I29) -> 10164 | J30: =SUM(J21:J29) -> 11701 | K30: =SUM(K21:K29) -> 13579 | L30: =SUM(L21:L29) -> 14882
B31: ='Raw Data'!B27 -> Accumulated Depreciation | G31: =-'Raw Data'!G27 -> -2500 | H31: =-'Raw Data'!H27 -> -3481 | I31: =-'Raw Data'!I27 -> -4105 | J31: =-'Raw Data'!J27 -> -4886 | K31: =-'Raw Data'!K27 -> -5707 | L31: =-'Raw Data'!L27 -> -6429
A32: # | B32: Net Non-Current Asset | G32: =SUM(G30:G31) -> 4897 | H32: =SUM(H30:H31) -> 6026 | I32: =SUM(I30:I31) -> 6059 | J32: =SUM(J30:J31) -> 6815 | K32: =SUM(K30:K31) -> 7872 | L32: =SUM(L30:L31) -> 8453
A34: # | B34: Invested Capital(Net Working Capital) | G34: =G18+G32 -> 8475 | H34: =H18+H32 -> 2011 | I34: =I18+I32 -> 4460 | J34: =J18+J32 -> 7299 | K34: =K18+K32 -> 4043 | L34: =L18+L32 -> 4048
B35: EBIT | G35: =IFERROR(HistoricalFS!D27+HistoricalFS!D21,0) -> 6040 | H35: =IFERROR(HistoricalFS!E27+HistoricalFS!E21,0) -> 6907 | I35: =IFERROR(HistoricalFS!F27+HistoricalFS!F21,0) -> 8327 | J35: =IFERROR(HistoricalFS!G27+HistoricalFS!G21,0) -> 8751 | K35: =IFERROR(HistoricalFS!H27+HistoricalFS!H21,0) -> 10147 | L35: =IFERROR(HistoricalFS!I27+HistoricalFS!I21,0) -> 11744
A37: # | B37: ROIC | G37: =G35/G34 -> 0.71268437 | H37: =H35/H34 -> 3.4346096 | I37: =I35/I34 -> 1.8670404 | J37: =J35/J34 -> 1.1989314 | K37: =K35/K34 -> 2.50977 | L37: =L35/L34 -> 2.9011858
A39: # | B39: Calculation Of ROIC | G39: =G3 -> 43921 | H39: =H3 -> 44286 | I39: =I3 -> 44651 | J39: =J3 -> 45016 | K39: =K3 -> 45382 | L39: =L3 -> 45747
B41: Net CAPEX | G41: =-SUM('Raw Data'!G55:G56) -> 810 | H41: =-SUM('Raw Data'!H55:H56) -> 4066 | I41: =-SUM('Raw Data'!I55:I56) -> 1053 | J41: =-SUM('Raw Data'!J55:J56) -> 1011 | K41: =-SUM('Raw Data'!K55:K56) -> 1457 | L41: =-SUM('Raw Data'!L55:L56) -> 1262
B42: Change in Working Capital | H42: =H18-G18 -> -7593 | I42: =I18-H18 -> 2416 | J42: =J18-I18 -> 2083 | K42: =K18-J18 -> -4313 | L42: =L18-K18 -> -576
B44: EBIT | G44: =G35 -> 6040 | H44: =H35 -> 6907 | I44: =I35 -> 8327 | J44: =J35 -> 8751 | K44: =K35 -> 10147 | L44: =L35 -> 11744
B45: Marginal Tax | G45: 0.25 | H45: 0.25 | I45: 0.25 | J45: 0.25 | K45: 0.25 | L45: 0.25
B46: EBIT(1-T) | G46: =G44*(1-G45) -> 4530 | H46: =H44*(1-H45) -> 5180.25 | I46: =I44*(1-I45) -> 6245.25 | J46: =J44*(1-J45) -> 6563.25 | K46: =K44*(1-K45) -> 7610.25 | L46: =L44*(1-L45) -> 8808
B48: Reinvestment | G48: =SUM(G41:G42) -> 810 | H48: =SUM(H41:H42) -> -3527 | I48: =SUM(I41:I42) -> 3469 | J48: =SUM(J41:J42) -> 3094 | K48: =SUM(K41:K42) -> -2856 | L48: =SUM(L41:L42) -> 686
B50: Reinvestment Rate | G50: =G48/G46 -> 0.17880795 | H50: =H48/H46 -> -0.68085517 | I50: =I48/I46 -> 0.55546215 | J50: =J48/J46 -> 0.47141279 | K50: =K48/K46 -> -0.37528333 | L50: =L48/L46 -> 0.077883742
I52: 4 year Average | K52: =AVERAGE(H50:K50) -> -0.007315891 | L52: =AVERAGE(I50:L50) -> 0.18236884
I53: 4 year Median | K53: =MEDIAN(H50:K50) -> 0.048064728 | L53: =MEDIAN(I50:L50) -> 0.27464827
A55: # | B55: Calculation Of Growth Rate | G55: ='Raw Data'!$G$2 -> 43891 | H55: ='Raw Data'!$H$2 -> 44256 | I55: ='Raw Data'!$I$2 -> 44621 | J55: ='Raw Data'!$J$2 -> 44986 | K55: ='Raw Data'!$K$2 -> 45352 | L55: ='Raw Data'!$K$2 -> 45352
B57: Reinvestment Rate | G57: =G50 -> 0.17880795 | H57: =H50 -> -0.68085517 | I57: =I50 -> 0.55546215 | J57: =J50 -> 0.47141279 | K57: =K50 -> -0.37528333 | L57: =L50 -> 0.077883742
...

Sheet Raw Data
B1: Balance Sheet of Hindustan Unilever
B2: Particulars | C2: =HistoricalFS!C3 -> 42430 | D2: =HistoricalFS!D3 -> 42795 | E2: =HistoricalFS!E3 -> 43160 | F2: =HistoricalFS!F3 -> 43525 | G2: =HistoricalFS!G3 -> 43891 | H2: =HistoricalFS!H3 -> 44256 | I2: =HistoricalFS!I3 -> 44621 | J2: =HistoricalFS!J3 -> 44986 | ... L2: =HistoricalFS!L3 -> 45717
B3: Equity Capital | C3: 216 | D3: 216 | E3: 216 | F3: 216 | G3: 216 | H3: 235 | I3: 235 | J3: 235 | K3: 235 | L3: 235
B4: Reserves | C4: 6357 | D4: 6528 | E4: 7065 | F4: 7651 | G4: 8013 | H4: 47439 | I4: 48826 | J4: 50069 | K4: 50983 | L4: 49167
B5: Borrowings -
B6: Long term Borrowings | C6: 0 | D6: 0 | E6: 0 | F6: 0 | G6: 0 | H6: 0 | I6: 0 | J6: 0 | K6: 0 | L6: 0
B7: Short term Borrowings | C7: 177 | D7: 277 | E7: 0 | F7: 99 | G7: 0 | H7: 0 | I7: 0 | J7: 98 | K7: 13 | L7: 1
B8: Lease Liabilities | C8: 0 | D8: 0 | E8: 0 | F8: 0 | G8: 0 | H8: 0 | I8: 1043 | J8: 1121 | K8: 1471 | L8: 1647
B9: Other Liabilities -
B10: Non controlling int | C10: 20 | D10: 22 | E10: 20 | F10: 18 | G10: 17 | H10: 20 | I10: 26 | J10: 218 | K10: 205 | L10: 207
B11: Trade Payables | C11: 5685 | D11: 6186 | E11: 7170 | F11: 7206 | G11: 7535 | H11: 8802 | I11: 9068 | J11: 9574 | K11: 10486 | L11: 11315
B12: Advance from Customers | C12: 45 | D12: 78 | E12: 62 | F12: 43 | G12: 158 | H12: 96 | I12: 119 | J12: 98 | K12: 91 | L12: 105
B13: Other liability items | C13: 2293 | D13: 2399 | E13: 3329 | F13: 3396 | G13: 4214 | H13: 12148 | I13: 11189 | J13: 11664 | K13: 15005 | L13: 17186
B14: Total Liabilities | C14: 14793 | D14: 15706 | E14: 17862 | F14: 18629 | G14: 20153 | H14: 68740 | I14: 70506 | J14: 73077 | K14: 78489 | L14: 79863
B16: Fixed Assets -
B17: Land | C17: 88 | D17: 89 | E17: 87 | F17: 86 | G17: 59 | H17: 477 | I17: 477 | J17: 609 | K17: 633 | L17: 628
B18: Building | C18: 931 | D18: 1210 | E18: 1343 | F18: 1527 | G18: 2044 | H18: 2602 | I18: 2788 | J18: 3101 | K18: 3590 | L18: 3833
B19: Plant Machinery | C19: 2370 | D19: 3270 | E19: 3691 | F19: 4092 | G19: 5001 | H19: 6097 | I19: 6566 | J19: 7612 | K19: 8946 | L19: 9900
B20: Equipments | C20: 41 | D20: 62 | E20: 74 | F20: 95 | G20: 139 | H20: 175 | I20: 181 | J20: 185 | K20: 206 | L20: 245
B21: Furniture n fittings | C21: 61 | D21: 66 | E21: 76 | F21: 88 | G21: 154 | H21: 156 | I21: 152 | J21: 161 | K21: 165 | L21: 174
B22: Railway sidings | C22: 0 | D22: 0 | E22: 0 | F22: 0 | G22: 0 | H22: 0 | I22: 0 | J22: 0 | K22: 0 | L22: 0
B23: Vehicles | C23: 0 | D23: 0 | E23: 0 | F23: 0 | G23: 0 | H23: 0 | I23: 0 | J23: 0 | K23: 0 | L23: 0
B24: Intangible Assets | C24: 0 | D24: 0 | E24: 0 | F24: 0 | G24: 0 | H24: 0 | I24: 0 | J24: 33 | K24: 39 | L24: 102
B25: Other fixed assets | C25: 85 | D25: 455 | E25: 455 | F25: 511 | G25: 511 | H25: 45262 | I25: 45262 | J25: 45692 | K25: 45692 | L25: 45692
B26: Gross Block | C26: 3744 | D26: 3914 | E26: 4705 | F26: 8141 | G26: 8282 | H26: 8392 | I26: 8538 | J26: 9676 | K26: 11622 | L26: 11622
B27: Accumulated Depreciation | C27: 337 | D27: 752 | E27: 1224 | F27: 1744 | G27: 2500 | H27: 3481 | I27: 4105 | J27: 4886 | K27: 5707 | L27: 6429
B28: Net Block | C28: =C26-C27 -> 3407 | D28: =D26-D27 -> 3162 | E28: =E26-E27 -> 3481 | F28: =F26-F27 -> 6397 | G28: =G26-G27 -> 5782 | H28: =H26-H27 -> 4911 | I28: =I26-I27 -> 4433 | J28: =J26-J27 -> 4790 | ... L28: =L26-L27 -> 5193
B30: CWIP | C30: 408 | D30: 229 | E30: 461 | F30: 406 | G30: 597 | H30: 745 | I30: 1313 | J30: 1132 | K30: 1025 | L30: 1009
B31: Investments | C31: 2592 | D31: 3794 | E31: 2873 | F31: 2716 | G31: 1255 | H31: 2709 | I31: 3521 | J31: 2882 | K31: 4625 | L31: 3810
B33: Other Assets -
B34: Inventories | C34: 2726 | D34: 2541 | E34: 2513 | F34: 2574 | G34: 2767 | H34: 3579 | I34: 4096 | J34: 4251 | K34: 4022 | L34: 4415
B35: Trade receivables - | C35: 1264 | D35: 1085 | E35: 1310 | F35: 1816 | G35: 1149 | H35: 1758 | I35: 2236 | J35: 3079 | K35: 2997 | L35: 3819
B36: Receivables over 6m | C36: 0 | D36: 0 | E36: 0 | F36: 0 | G36: 0 | H36: 0 | I36: 197 | J36: 407 | K36: 200 | L36: 313
B37: Receivables under 6m | C37: 1294 | D37: 1124 | E37: 1359 | F37: 1848 | G37: 1185 | H37: 1869 | I37: 2142 | J37: 2748 | K37: 2862 | L37: 3574
B38: Prov for Doubtful | C38: -30 | D38: -39 | E38: -49 | F38: -32 | G38: -36 | H38: -111 | I38: -103 | J38: -76 | K38: -65 | L38: -68
B39: Cash Equivalents | C39: 3009 | D39: 1828 | E39: 3485 | F39: 3757 | G39: 5113 | H39: 4471 | I39: 3846 | J39: 4678 | K39: 7559 | L39: 7554
B40: Loans n Advances | C40: 0 | D40: 71 | E40: 40 | F40: 26 | G40: 19 | H40: 78 | I40: 170 | J40: 188 | K40: 172 | L40: 242
B41: Other asset items | C41: 1536 | D41: 1739 | E41: 2652 | F41: 2619 | G41: 3774 | H41: 3957 | I41: 3851 | J41: 4189 | K41: 4345 | L41: 4679
B42: Total Assets | C42: 14793 | D42: 15706 | E42: 17862 | F42: 18629 | G42: 20153 | H42: 68740 | I42: 70506 | J42: 73077 | K42: 78489 | L42: 79863
B45: Cash from Operating Activity -
...

Sheet HistoricalFS
B2: Historical Financial Statements - Hindustan Unilever
B3: Years | C3: ='Cash Flow Statement'!C3 -> 42430 | D3: ='Cash Flow Statement'!D3 -> 42795 | E3: ='Cash Flow Statement'!E3 -> 43160 | F3: ='Cash Flow Statement'!F3 -> 43525 | G3: ='Cash Flow Statement'!G3 -> 43891 | H3: ='Cash Flow Statement'!H3 -> 44256 | I3: ='Cash Flow Statement'!I3 -> 44621 | J3: ='Cash Flow Statement'!J3 -> 44986 | ... L3: ='Cash Flow Statement'!L3 -> 45717 | M3: LTM
A5: # | B5: Income Statement
B6: Sales | C6: ='Data Sheet'!B17 -> 32186 | D6: ='Data Sheet'!C17 -> 33162 | E6: ='Data Sheet'!D17 -> 35545 | F6: ='Data Sheet'!E17 -> 39310 | G6: ='Data Sheet'!F17 -> 39783 | H6: ='Data Sheet'!G17 -> 47028 | I6: ='Data Sheet'!H17 -> 52446 | J6: ='Data Sheet'!I17 -> 60580 | ... L6: ='Data Sheet'!K17 -> 63121 | M6: =IFERROR(SUM(C6:L6),0) -> 465057
B7: Sales Growth | D7: =D6/C6-1 -> 0.030323743 | E7: =E6/D6-1 -> 0.071859357 | F7: =F6/E6-1 -> 0.10592207 | G7: =G6/F6-1 -> 0.012032562 | H7: =H6/G6-1 -> 0.18211296 | I7: =I6/H6-1 -> 0.11520796 | J7: =J6/I6-1 -> 0.15509286 | K7: =K6/J6-1 -> 0.021723341 | ... M7: =M6/L6-1 -> 6.3677065
B9: COGS | C9: =IFERROR(SUM('Data Sheet'!B18,'Data Sheet'!B20:B22),0) -> 18139 | D9: =IFERROR(SUM('Data Sheet'!C18,'Data Sheet'!C20,'Data Sheet'!C21,'Data Sheet'!C22),0) -> 18531 | E9: =IFERROR(SUM('Data Sheet'!D18,'Data Sheet'!D20,'Data Sheet'!D21,'Data Sheet'!D22),0) -> 19386 | F9: =IFERROR(SUM('Data Sheet'!E18,'Data Sheet'!E20,'Data Sheet'!E21,'Data Sheet'!E22),0) -> 21069 | G9: =IFERROR(SUM('Data Sheet'!F18,'Data Sheet'!F20,'Data Sheet'!F21,'Data Sheet'!F22),0) -> 20722 | H9: =IFERROR(SUM('Data Sheet'!G18,'Data Sheet'!G20,'Data Sheet'!G21,'Data Sheet'!G22),0) -> 25706 | I9: =IFERROR(SUM('Data Sheet'!H18,'Data Sheet'!H20,'Data Sheet'!H21,'Data Sheet'!H22),0) -> 29088 | J9: =IFERROR(SUM('Data Sheet'!I18,'Data Sheet'!I20,'Data Sheet'!I21,'Data Sheet'!I22),0) -> 35456 | K9: =IFERROR(SUM('Data Sheet'!J18,'Data Sheet'!J20,'Data Sheet'!J21,'Data Sheet'!J22),0) -> 33662 | L9: =IFERROR(SUM('Data Sheet'!K18,'Data Sheet'!K20,'Data Sheet'!K21,'Data Sheet'!K22),0) -> 34682 | M9: =IFERROR(SUM(C9:L9),0) -> 256441
B10: COGS % Sales | C10: =C9/C6 -> 0.56356801 | D10: =D9/D6 -> 0.55880224 | E10: =E9/E6 -> 0.54539316 | F10: =F9/F6 -> 0.53597049 | G10: =G9/G6 -> 0.52087575 | H10: =H9/H6 -> 0.54661053 | I10: =I9/I6 -> 0.55462762 | J10: =J9/J6 -> 0.58527567 | ... M10: =M9/M6 -> 0.55141843
B12: Gross Profit | C12: =C6-C9 -> 14047 | D12: =D6-D9 -> 14631 | E12: =E6-E9 -> 16159 | F12: =F6-F9 -> 18241 | G12: =G6-G9 -> 19061 | H12: =H6-H9 -> 21322 | I12: =I6-I9 -> 23358 | J12: =J6-J9 -> 25124 | ... L12: =L6-L9 -> 28439 | M12: =IFERROR(SUM(C12:L12),0) -> 208616
B13: Gross Margin | C13: =C12/C6 -> 0.43643199 | D13: =D12/D6 -> 0.44119776 | E13: =E12/E6 -> 0.45460684 | F13: =F12/F6 -> 0.46402951 | G13: =G12/G6 -> 0.47912425 | H13: =H12/H6 -> 0.45338947 | I13: =I12/I6 -> 0.44537238 | J13: =J12/J6 -> 0.41472433 | ... M13: =M12/M6 -> 0.44858157
B15: Selling & General Exp | C15: =IFERROR(SUM('Data Sheet'!B23:B24),0) -> 8054 | D15: =IFERROR(SUM('Data Sheet'!C23:C24),0) -> 8159 | E15: =IFERROR(SUM('Data Sheet'!D23:D24),0) -> 8732 | F15: =IFERROR(SUM('Data Sheet'!E23:E24),0) -> 9349 | G15: =IFERROR(SUM('Data Sheet'!F23:F24),0) -> 9308 | H15: =IFERROR(SUM('Data Sheet'!G23:G24),0) -> 10101 | I15: =IFERROR(SUM('Data Sheet'!H23:H24),0) -> 10523 | J15: =IFERROR(SUM('Data Sheet'!I23:I24),0) -> 11052 | ... L15: =IFERROR(SUM('Data Sheet'!K23:K24),0) -> 13749 | M15: =IFERROR(SUM(C15:L15),0) -> 102613
B16: S&G % Sales | C16: =C15/C6 -> 0.25023302 | D16: =D15/D6 -> 0.24603462 | E16: =E15/E6 -> 0.24566043 | F16: =F15/F6 -> 0.23782752 | G16: =G15/G6 -> 0.23396928 | H16: =H15/H6 -> 0.21478694 | I16: =I15/I6 -> 0.20064447 | J16: =J15/J6 -> 0.18243645 | ... M16: =M15/M6 -> 0.22064607
B18: EBITDA | C18: =C12-C15 -> 5993 | D18: =D12-D15 -> 6472 | E18: =E12-E15 -> 7427 | F18: =F12-F15 -> 8892 | G18: =G12-G15 -> 9753 | H18: =H12-H15 -> 11221 | I18: =I12-I15 -> 12835 | J18: =J12-J15 -> 14072 | ... M18: =M12-M15 -> 106003
B19: EBITDA % Sales(EBITDA Margin) | C19: =C18/C6 -> 0.18619897 | D19: =D18/D6 -> 0.19516314 | E19: =E18/E6 -> 0.20894641 | F19: =F18/F6 -> 0.22620198 | G19: =G18/G6 -> 0.24515497 | H19: =H18/H6 -> 0.23860253 | I19: =I18/I6 -> 0.24472791 | J19: =J18/J6 -> 0.23228788 | ... M19: =M18/M6 -> 0.2279355
B21: Interest | C21: =IFERROR('Data Sheet'!B27,0) -> 17 | D21: =IFERROR('Data Sheet'!C27,0) -> 35 | E21: =IFERROR('Data Sheet'!D27,0) -> 26 | F21: =IFERROR('Data Sheet'!E27,0) -> 33 | G21: =IFERROR('Data Sheet'!F27,0) -> 118 | H21: =IFERROR('Data Sheet'!G27,0) -> 117 | I21: =IFERROR('Data Sheet'!H27,0) -> 106 | J21: =IFERROR('Data Sheet'!I27,0) -> 114 | ... L21: =IFERROR('Data Sheet'!K27,0) -> 395 | M21: =IFERROR(SUM(C21:L21),0) -> 1295
B22: Interest % Sales | C22: =C21/C6 -> 0.00052817995 | D22: =D21/D6 -> 0.0010554249 | E22: =E21/E6 -> 0.00073146715 | F22: =F21/F6 -> 0.00083948105 | G22: =G21/G6 -> 0.002966091 | H22: =H21/H6 -> 0.0024878796 | I22: =I21/I6 -> 0.0020211265 | J22: =J21/J6 -> 0.0018818092 | ... M22: =M21/M6 -> 0.0027846049
B24: Depreciation | C24: =IFERROR('Data Sheet'!B26,0) -> 353 | D24: =IFERROR('Data Sheet'!C26,0) -> 432 | E24: =IFERROR('Data Sheet'!D26,0) -> 520 | F24: =IFERROR('Data Sheet'!E26,0) -> 565 | G24: =IFERROR('Data Sheet'!F26,0) -> 1002 | H24: =IFERROR('Data Sheet'!G26,0) -> 1074 | I24: =IFERROR('Data Sheet'!H26,0) -> 1091 | J24: =IFERROR('Data Sheet'!I26,0) -> 1137 | ... L24: =IFERROR('Data Sheet'!K26,0) -> 1355 | M24: =IFERROR(SUM(C24:L24),0) -> 8745
B25: Depreciation % Sales | C25: =C24/C6 -> 0.010967501 | D25: =D24/D6 -> 0.013026959 | E25: =E24/E6 -> 0.014629343 | F25: =F24/F6 -> 0.014372933 | G25: =G24/G6 -> 0.025186638 | H25: =H24/H6 -> 0.022837459 | I25: =I24/I6 -> 0.020802349 | J25: =J24/J6 -> 0.01876857 | ... M25: =M24/M6 -> 0.018804147
B27: Earnings Before Tax | C27: =IFERROR(C18-SUM(C21,C24),0) -> 5623 | D27: =IFERROR(D18-SUM(D21,D24),0) -> 6005 | E27: =IFERROR(E18-SUM(E21,E24),0) -> 6881 | F27: =IFERROR(F18-SUM(F21,F24),0) -> 8294 | G27: =IFERROR(G18-SUM(G21,G24),0) -> 8633 | H27: =IFERROR(H18-SUM(H21,H24),0) -> 10030 | I27: =IFERROR(I18-SUM(I21,I24),0) -> 11638 | J27: =IFERROR(J18-SUM(J21,J24),0) -> 12821 | ... M27: =IFERROR(M18-SUM(M21,M24),0) -> 95963
B28: EBT % Tax | C28: =C27/C6 -> 0.17470329 | D28: =D27/D6 -> 0.18108076 | E28: =E27/E6 -> 0.1935856 | F28: =F27/F6 -> 0.21098957 | G28: =G27/G6 -> 0.21700224 | H28: =H27/H6 -> 0.2132772 | I28: =I27/I6 -> 0.22190444 | J28: =J27/J6 -> 0.2116375 | ... M28: =M27/M6 -> 0.20634675
B30: Tax | C30: =IFERROR('Data Sheet'!B29,0) -> 1875 | D30: =IFERROR('Data Sheet'!C29,0) -> 1977 | E30: =IFERROR('Data Sheet'!D29,0) -> 2079 | F30: =IFERROR('Data Sheet'!E29,0) -> 2544 | G30: =IFERROR('Data Sheet'!F29,0) -> 2409 | H30: =IFERROR('Data Sheet'!G29,0) -> 2606 | I30: =IFERROR('Data Sheet'!H29,0) -> 2987 | J30: =IFERROR('Data Sheet'!I29,0) -> 3201 | ... L30: =IFERROR('Data Sheet'!K29,0) -> 3744 | M30: =IFERROR(SUM(C30:L30),0) -> 27066
B31: Effective Tax Rate | C31: =C30/C27 -> 0.33345189 | D31: =D30/D27 -> 0.32922565 | E31: =E30/E27 -> 0.30213632 | F31: =F30/F27 -> 0.30672776 | G31: =G30/G27 -> 0.27904552 | H31: =H30/H27 -> 0.25982054 | I31: =I30/I27 -> 0.25665922 | J31: =J30/J27 -> 0.24966851 | ... M31: =M30/M27 -> 0.28204621
B33: Net Profit | C33: =C27-C30 -> 3748 | D33: =D27-D30 -> 4028 | E33: =E27-E30 -> 4802 | F33: =F27-F30 -> 5750 | G33: =G27-G30 -> 6224 | H33: =H27-H30 -> 7424 | I33: =I27-I30 -> 8651 | J33: =J27-J30 -> 9620 | ... M33: =M27-M30 -> 68897
B34: Net Margins | C34: =C33/C6 -> 0.11644815 | D34: =D33/D6 -> 0.12146433 | E34: =E33/E6 -> 0.13509636 | F34: =F33/F6 -> 0.14627321 | G34: =G33/G6 -> 0.15644873 | H34: =H33/H6 -> 0.1578634 | I34: =I33/I6 -> 0.16495062 | J34: =J33/J6 -> 0.15879828 | ... M34: =M33/M6 -> 0.14814743
B37: No, of Equity | C37: =IFERROR('Data Sheet'!B93,0) -> 216.39 | D37: =IFERROR('Data Sheet'!C93,0) -> 216.43 | E37: =IFERROR('Data Sheet'!D93,0) -> 216.45 | F37: =IFERROR('Data Sheet'!E93,0) -> 216.47 | G37: =IFERROR('Data Sheet'!F93,0) -> 216.48 | H37: =IFERROR('Data Sheet'!G93,0) -> 234.96 | I37: =IFERROR('Data Sheet'!H93,0) -> 234.96 | J37: =IFERROR('Data Sheet'!I93,0) -> 234.96 | ... L37: =IFERROR('Data Sheet'!K93,0) -> 234.96 | M37: =IFERROR(M31/M35,0) -> 0
B39: Earnings Per Share | C39: =IFERROR(C33/C37,0) -> 17.320579 | D39: =IFERROR(D33/D37,0) -> 18.611098 | E39: =IFERROR(E33/E37,0) -> 22.185262 | F39: =IFERROR(F33/F37,0) -> 26.562572 | G39: =IFERROR(G33/G37,0) -> 28.750924 | H39: =IFERROR(H33/H37,0) -> 31.596868 | I39: =IFERROR(I33/I37,0) -> 36.819033 | J39: =IFERROR(J33/J37,0) -> 40.943139 | ... M39: =IFERROR(M33/M37,0) -> 0
B40: EPS Growth % | D40: =IFERROR(D39-C39,0) -> 1.2905197 | E40: =IFERROR(E39-D39,0) -> 3.5741639 | F40: =IFERROR(F39-E39,0) -> 4.37731 | G40: =IFERROR(G39-F39,0) -> 2.1883517 | H40: =IFERROR(H39-G39,0) -> 2.8459437 | I40: =IFERROR(I39-H39,0) -> 5.2221655 | J40: =IFERROR(J39-I39,0) -> 4.1241062 | K40: =IFERROR(K39-J39,0) -> -0.70650323 | L40: =IFERROR(L39-K39,0) -> -1.0980592
B42: Dividened Per Share | C42: =IFERROR('Data Sheet'!B31/HistoricalFS!C39,0) -> 199.53144 | D42: =IFERROR('Data Sheet'!C31/HistoricalFS!D39,0) -> 197.30163 | E42: =IFERROR('Data Sheet'!D31/HistoricalFS!E39,0) -> 194.72387 | F42: =IFERROR('Data Sheet'!E31/HistoricalFS!F39,0) -> 178.89834 | G42: =IFERROR('Data Sheet'!F31/HistoricalFS!G39,0) -> 187.82005 | H42: =IFERROR('Data Sheet'!G31/HistoricalFS!H39,0) -> 301.21657 | I42: =IFERROR('Data Sheet'!H31/HistoricalFS!I39,0) -> 217.00733 | J42: =IFERROR('Data Sheet'!I31/HistoricalFS!J39,0) -> 223.84703 | ... M42: =IFERROR('Data Sheet'!L31/HistoricalFS!M39,0) -> 0
B43: Dividened Payout Ratio | C43: =IFERROR(C42/C39,0) -> 11.519906 | D43: =IFERROR(D42/D39,0) -> 10.601289 | E43: =IFERROR(E42/E39,0) -> 8.7771721 | F43: =IFERROR(F42/F39,0) -> 6.7349779 | G43: =IFERROR(G42/G39,0) -> 6.5326614 | H43: =IFERROR(H42/H39,0) -> 9.5331149 | I43: =IFERROR(I42/I39,0) -> 5.8938899 | J43: =IFERROR(J42/J39,0) -> 5.4672658 | ... M43: =IFERROR(M42/M39,0) -> 0
B45: Retained Earnings | C45: =IFERROR(1-C43,0) -> -10.519906 | D45: =IFERROR(1-D43,0) -> -9.6012888 | E45: =IFERROR(1-E43,0) -> -7.7771721 | F45: =IFERROR(1-F43,0) -> -5.7349779 | G45: =IFERROR(1-G43,0) -> -5.5326614 | H45: =IFERROR(1-H43,0) -> -8.5331149 | I45: =IFERROR(1-I43,0) -> -4.8938899 | J45: =IFERROR(1-J43,0) -> -4.4672658 | ... M45: =IFERROR(1-M43,0) -> 1
B46: Retained Earnings | C46: =IFERROR(IF(C37>C39,1-C43,0),0) -> -10.519906 | D46: =IFERROR(IF(D37>D39,1-D43,0),0) -> -9.6012888 | E46: =IFERROR(IF(E37>E39,1-E43,0),0) -> -7.7771721 | F46: =IFERROR(IF(F37>F39,1-F43,0),0) -> -5.7349779 | G46: =IFERROR(IF(G37>G39,1-G43,0),0) -> -5.5326614 | H46: =IFERROR(IF(H37>H39,1-H43,0),0) -> -8.5331149 | I46: =IFERROR(IF(I37>I39,1-I43,0),0) -> -4.8938899 | J46: =IFERROR(IF(J37>J39,1-J43,0),0) -> -4.4672658 | ... M46: =IFERROR(IF(M37>M39,1-M43,0),0) -> 0
A48: # | B48: Balance Sheet
B49: Equity Share Capital | C49: =IFERROR('Data Sheet'!B57,0) -> 216 | D49: =IFERROR('Data Sheet'!C57,0) -> 216 | E49: =IFERROR('Data Sheet'!D57,0) -> 216 | F49: =IFERROR('Data Sheet'!E57,0) -> 216 | G49: =IFERROR('Data Sheet'!F57,0) -> 216 | H49: =IFERROR('Data Sheet'!G57,0) -> 235 | I49: =IFERROR('Data Sheet'!H57,0) -> 235 | J49: =IFERROR('Data Sheet'!I57,0) -> 235 | ... M49: =IFERROR('Data Sheet'!L57,0) -> 0
B50: Reserves | C50: =IFERROR('Data Sheet'!B58,0) -> 6357 | D50: =IFERROR('Data Sheet'!C58,0) -> 6528 | E50: =IFERROR('Data Sheet'!D58,0) -> 7065 | F50: =IFERROR('Data Sheet'!E58,0) -> 7651 | G50: =IFERROR('Data Sheet'!F58,0) -> 8013 | H50: =IFERROR('Data Sheet'!G58,0) -> 47439 | I50: =IFERROR('Data Sheet'!H58,0) -> 48826 | J50: =IFERROR('Data Sheet'!I58,0) -> 50069 | ... M50: =IFERROR('Data Sheet'!L58,0) -> 0
B51: Borrowings | C51: =IFERROR('Data Sheet'!B59,0) -> 177 | D51: =IFERROR('Data Sheet'!C59,0) -> 277 | E51: =IFERROR('Data Sheet'!D59,0) -> 0 | F51: =IFERROR('Data Sheet'!E59,0) -> 99 | G51: =IFERROR('Data Sheet'!F59,0) -> 0 | H51: =IFERROR('Data Sheet'!G59,0) -> 0 | I51: =IFERROR('Data Sheet'!H59,0) -> 1043 | J51: =IFERROR('Data Sheet'!I59,0) -> 1219 | ... M51: =IFERROR('Data Sheet'!L59,0) -> 0
B52: Other Liabilities | C52: =IFERROR('Data Sheet'!B60,0) -> 8043 | D52: =IFERROR('Data Sheet'!C60,0) -> 8685 | E52: =IFERROR('Data Sheet'!D60,0) -> 10581 | F52: =IFERROR('Data Sheet'!E60,0) -> 10663 | G52: =IFERROR('Data Sheet'!F60,0) -> 11924 | H52: =IFERROR('Data Sheet'!G60,0) -> 21066 | I52: =IFERROR('Data Sheet'!H60,0) -> 20402 | J52: =IFERROR('Data Sheet'!I60,0) -> 21554 | ... M52: =IFERROR('Data Sheet'!L60,0) -> 0
B53: Total Liabilities | C53: =SUM(C49:C52) -> 14793 | D53: =SUM(D49:D52) -> 15706 | E53: =SUM(E49:E52) -> 17862 | F53: =SUM(F49:F52) -> 18629 | G53: =SUM(G49:G52) -> 20153 | H53: =SUM(H49:H52) -> 68740 | I53: =SUM(I49:I52) -> 70506 | J53: =SUM(J49:J52) -> 73077 | ... M53: =SUM(M49:M52) -> 0
B55: Fixed Asset Net Block | C55: =IFERROR('Data Sheet'!B62,0) -> 3258 | D55: =IFERROR('Data Sheet'!C62,0) -> 4419 | E55: =IFERROR('Data Sheet'!D62,0) -> 4528 | F55: =IFERROR('Data Sheet'!E62,0) -> 4715 | G55: =IFERROR('Data Sheet'!F62,0) -> 5479 | H55: =IFERROR('Data Sheet'!G62,0) -> 51443 | I55: =IFERROR('Data Sheet'!H62,0) -> 51473 | J55: =IFERROR('Data Sheet'!I62,0) -> 52678 | ... M55: =IFERROR('Data Sheet'!L62,0) -> 0
B56: Capital Work in Progress | C56: =IFERROR('Data Sheet'!B63,0) -> 408 | D56: =IFERROR('Data Sheet'!C63,0) -> 229 | E56: =IFERROR('Data Sheet'!D63,0) -> 461 | F56: =IFERROR('Data Sheet'!E63,0) -> 406 | G56: =IFERROR('Data Sheet'!F63,0) -> 597 | H56: =IFERROR('Data Sheet'!G63,0) -> 745 | I56: =IFERROR('Data Sheet'!H63,0) -> 1313 | J56: =IFERROR('Data Sheet'!I63,0) -> 1132 | ... M56: =IFERROR('Data Sheet'!L63,0) -> 0
B57: Investments | C57: =IFERROR('Data Sheet'!B64,0) -> 2592 | D57: =IFERROR('Data Sheet'!C64,0) -> 3794 | E57: =IFERROR('Data Sheet'!D64,0) -> 2873 | F57: =IFERROR('Data Sheet'!E64,0) -> 2716 | G57: =IFERROR('Data Sheet'!F64,0) -> 1255 | H57: =IFERROR('Data Sheet'!G64,0) -> 2709 | I57: =IFERROR('Data Sheet'!H64,0) -> 3521 | J57: =IFERROR('Data Sheet'!I64,0) -> 2882 | ... M57: =IFERROR('Data Sheet'!L64,0) -> 0
B58: Other Assets | C58: =IFERROR('Data Sheet'!B65-(SUM('Data Sheet'!B67:B69)),0) -> 1536 | D58: =IFERROR('Data Sheet'!C65-(SUM('Data Sheet'!C67:C69)),0) -> 1810 | E58: =IFERROR('Data Sheet'!D65-(SUM('Data Sheet'!D67:D69)),0) -> 2692 | F58: =IFERROR('Data Sheet'!E65-(SUM('Data Sheet'!E67:E69)),0) -> 2645 | G58: =IFERROR('Data Sheet'!F65-(SUM('Data Sheet'!F67:F69)),0) -> 3793 | H58: =IFERROR('Data Sheet'!G65-(SUM('Data Sheet'!G67:G69)),0) -> 4035 | I58: =IFERROR('Data Sheet'!H65-(SUM('Data Sheet'!H67:H69)),0) -> 4021 | J58: =IFERROR('Data Sheet'!I65-(SUM('Data Sheet'!I67:I69)),0) -> 4377 | ... M58: =IFERROR('Data Sheet'!L65-(SUM('Data Sheet'!L67:L69)),0) -> 0
...

Sheet Data Sheet
A1: COMPANY NAME | B1: HINDUSTAN UNILEVER LTD | E1: =IF(B2<>B3, "A NEW VERSION OF THE WORKSHEET IS AVAILABLE", "")
A2: LATEST VERSION | B2: 2.1 | E2: PLEASE DO NOT MAKE ANY CHANGES TO THIS SHEET
A3: CURRENT VERSION | B3: 2.1
A5: META
A6: Number of shares | B6: =IF(B9>0, B9/B8, 0) -> 234.95912
A7: Face Value | B7: 1
A8: Current Price | B8: 2134.8
A9: Market Capitalization | B9: 501590.74
A15: PROFIT & LOSS
A16: Report Date | B16: 42460 | C16: 42825 | D16: 43190 | E16: 43555 | F16: 43921 | G16: 44286 | H16: 44651 | I16: 45016 | J16: 45382 | K16: 45747
A17: Sales | B17: 32186 | C17: 33162 | D17: 35545 | E17: 39310 | F17: 39783 | G17: 47028 | H17: 52446 | I17: 60580 | J17: 61896 | K17: 63121
A18: Raw Material Cost | B18: 13184 | C18: 13606 | D18: 14233 | E18: 15845 | F18: 15697 | G18: 20141 | H18: 22871 | I18: 28427 | J18: 26822 | K18: 27344
A19: Change in Inventory | B19: -83 | C19: -144 | D19: 72 | E19: -12 | F19: 108 | G19: 405 | H19: 22 | I19: 75 | J19: 11 | K19: 153
A20: Power and Fuel | B20: 309 | C20: 295 | D20: 295 | E20: 308 | F20: 299 | G20: 339 | H20: 318 | I20: 384 | J20: 446 | K20: 427
A21: Other Mfr. Exp | B21: 2966 | C21: 2887 | D21: 2998 | E21: 3041 | F21: 2906 | G21: 2868 | H21: 3354 | I21: 3791 | J21: 3385 | K21: 3834
A22: Employee Cost | B22: 1680 | C22: 1743 | D22: 1860 | E22: 1875 | F22: 1820 | G22: 2358 | H22: 2545 | I22: 2854 | J22: 3009 | K22: 3077
A23: Selling and admin | B23: 6741 | C23: 6689 | D23: 7252 | E23: 7796 | F23: 7620 | G23: 7906 | H23: 8164 | I23: 8785 | J23: 10780 | K23: 10693
A24: Other Expenses | B24: 1313 | C24: 1470 | D24: 1480 | E24: 1553 | F24: 1688 | G24: 2195 | H24: 2359 | I24: 2267 | J24: 2806 | K24: 3056
A25: Other Income | B25: 486 | C25: 606 | D25: 353 | E25: 322 | F25: 424 | G25: 170 | H25: 219 | I25: 448 | J25: 817 | K25: 1322
A26: Depreciation | B26: 353 | C26: 432 | D26: 520 | E26: 565 | F26: 1002 | G26: 1074 | H26: 1091 | I26: 1137 | J26: 1216 | K26: 1355
A27: Interest | B27: 17 | C27: 35 | D27: 26 | E27: 33 | F27: 118 | G27: 117 | H27: 106 | I27: 114 | J27: 334 | K27: 395
... A31: Dividend Amount | B31: 3456 | C31: 3672 | D31: 4320 | E31: 4752 | F31: 5400 | G31: 9517.5 | H31: 7990 | I31: 9165 | J31: 9870 | K31: 12455
A40: Quarters
A41: Report Date | B41: 45199 | C41: 45291 | D41: 45382 | E41: 45473 | F41: 45565 | G41: 45657 | H41: 45747 | I41: 45838 | J41: 45930 | K41: 46022
A42: Sales | B42: 15623 | C42: 15567 | D42: 15210 | E42: 15707 | F42: 15926 | G42: 15556 | H42: 15670 | I42: 16514 | J42: 15919 | K42: 16441
A43: Expenses | B43: 11828 | C43: 11902 | D43: 11675 | E43: 11965 | F43: 12139 | G43: 11867 | H43: 12052 | I43: 12797 | J43: 12137 | K43: 12660
A44: Other Income | B44: 178 | C44: 184 | D44: 309 | E44: 209 | F44: 203 | G44: 733 | H44: 171 | I44: 74 | J44: 269 | K44: 4048
A45: Depreciation | B45: 297 | C45: 313 | D45: 320 | E45: 329 | F45: 338 | G45: 318 | H45: 347 | I45: 361 | J45: 322 | K45: 337
A46: Interest | B46: 88 | C46: 91 | D46: 105 | E46: 93 | F46: 110 | G46: 109 | H46: 80 | I46: 127 | J46: 124 | K46: 88
A47: Profit before tax | B47: 3588 | C47: 3445 | D47: 3419 | E47: 3529 | F47: 3542 | G47: 3995 | H47: 3362 | I47: 3303 | J47: 3605 | K47: 7404
A48: Tax | B48: 931 | C48: 937 | D48: 858 | E48: 917 | F48: 947 | G48: 1006 | H48: 887 | I48: 535 | J48: 911 | K48: 801
A49: Net profit | B49: 2656 | C49: 2509 | D49: 2558 | E49: 2610 | F49: 2591 | G49: 2984 | H49: 2464 | I49: 2756 | J49: 2685 | K49: 6607
A50: Operating Profit | B50: 3795 | C50: 3665 | D50: 3535 | E50: 3742 | F50: 3787 | G50: 3689 | H50: 3618 | I50: 3717 | J50: 3782 | K50: 3781
A55: BALANCE SHEET
A56: Report Date | B56: 42460 | C56: 42825 | D56: 43190 | E56: 43555 | F56: 43921 | G56: 44286 | H56: 44651 | I56: 45016 | J56: 45382 | K56: 45747
A57: Equity Share Capital | B57: 216 | C57: 216 | D57: 216 | E57: 216 | F57: 216 | G57: 235 | H57: 235 | I57: 235 | J57: 235 | K57: 235
A58: Reserves | B58: 6357 | C58: 6528 | D58: 7065 | E58: 7651 | F58: 8013 | G58: 47439 | H58: 48826 | I58: 50069 | J58: 50983 | K58: 49167
A59: Borrowings | B59: 177 | C59: 277 | E59: 99 | H59: 1043 | I59: 1219 | J59: 1484 | K59: 1648
A60: Other Liabilities | B60: 8043 | C60: 8685 | D60: 10581 | E60: 10663 | F60: 11924 | G60: 21066 | H60: 20402 | I60: 21554 | J60: 25787 | K60: 28813
A61: Total | B61: 14793 | C61: 15706 | D61: 17862 | E61: 18629 | F61: 20153 | G61: 68740 | H61: 70506 | I61: 73077 | J61: 78489 | K61: 79863
...

Sheet Cash Flow Statement
C3: 42430 | D3: 42795 | E3: 43160 | F3: 43525 | G3: 43891 | H3: 44256 | I3: 44621 | J3: 44986 | K3: 45352 | L3: 45717
B4: Cash from Operating Activity - | C4: 4171 | D4: 5185 | E4: 6059 | F4: 5800 | G4: 7623 | H4: 9163 | I4: 9048 | J4: 9991 | K4: 15469 | L4: 11886
B5: Profit from operations | C5: 6025 | D5: 6512 | E5: 7485 | F5: 8909 | G5: 9723 | H5: 11672 | I5: 12829 | J5: 14089 | K5: 14537 | L5: 14942
B6: Receivables | C6: -257 | D6: 173 | E6: 0 | F6: 0 | G6: 0 | H6: 0 | I6: 0 | J6: 0 | K6: 0 | L6: 0
B7: Inventory | C7: 89 | D7: 37 | E7: -146 | F7: -195 | G7: -331 | H7: -543 | I7: -758 | J7: -339 | K7: 74 | L7: -584
B8: Payables | C8: 164 | D8: 501 | E8: 0 | F8: 0 | G8: 0 | H8: 0 | I8: 0 | J8: 0 | K8: 0 | L8: 0
B9: Loans Advances | C9: 0 | D9: 0 | E9: 0 | F9: 0 | G9: 0 | H9: 0 | I9: 0 | J9: 0 | K9: 0 | L9: 0
B10: Operating Deposits | C10: 0 | D10: -46 | E10: 0 | F10: 0 | G10: 0 | H10: 0 | I10: 0 | J10: 0 | K10: 0 | L10: 0
B11: Other WC items | C11: -77 | D11: -99 | E11: 982 | F11: -147 | G11: 742 | H11: 442 | I11: -242 | J11: -621 | K11: 1239 | L11: -204
B12: Working capital changes | C12: -81 | D12: 566 | E12: 836 | F12: -342 | G12: 411 | H12: -101 | I12: -1000 | J12: -960 | K12: 1313 | L12: -788
B13: Direct taxes | C13: -1765 | D13: -1859 | E13: -2264 | F13: -2767 | G13: -2505 | H13: -2407 | I13: -2784 | J13: -3138 | K13: -381 | L13: -2268
B14: Other operating items | C14: -8 | D14: -21 | E14: 0 | F14: 0 | G14: 0 | H14: 0 | I14: 0 | J14: 0 | K14: 0 | L14: 0
B15: Exceptional CF items | C15: 0 | D15: -13 | E15: 2 | F15: 0 | G15: -6 | H15: -1 | I15: 3 | J15: 0 | K15: 0 | L15: 0
... B38: Net Cash Flow | C38: 25 | D38: -202 | E38: 21 | F38: -28 | G38: 2595 | H38: -1374 | I38: -695 | J38: -446 | K38: 111 | L38: 5258

Sheet Variance Analysis
B1: Hindustan Unilever Ltd — Variance Analysis (FY2016–FY2025)
B2: All figures in ₹ Crores | Source: Screener.in
B4: SECTION 1 — REVENUE & PROFIT (₹ Cr)
B5: Particulars | C5: FY16 | D5: FY17 | E5: FY18 | F5: FY19 | G5: FY20 | H5: FY21 | I5: FY22 | J5: FY23 | K5: FY24 | L5: FY25
B6: Sales | C6: ='Data Sheet'!B17 -> 32186 | D6: ='Data Sheet'!C17 -> 33162 | E6: ='Data Sheet'!D17 -> 35545 | F6: ='Data Sheet'!E17 -> 39310 | G6: ='Data Sheet'!F17 -> 39783 | H6: ='Data Sheet'!G17 -> 47028 | I6: ='Data Sheet'!H17 -> 52446 | J6: ='Data Sheet'!I17 -> 60580 | ... L6: ='Data Sheet'!K17 -> 63121
B7: Raw Material Cost | C7: ='Data Sheet'!B18 -> 13184 | D7: ='Data Sheet'!C18 -> 13606 | E7: ='Data Sheet'!D18 -> 14233 | F7: ='Data Sheet'!E18 -> 15845 | G7: ='Data Sheet'!F18 -> 15697 | H7: ='Data Sheet'!G18 -> 20141 | I7: ='Data Sheet'!H18 -> 22871 | J7: ='Data Sheet'!I18 -> 28427 | ... L7: ='Data Sheet'!K18 -> 27344
B8: Employee Cost | C8: ='Data Sheet'!B22 -> 1680 | D8: ='Data Sheet'!C22 -> 1743 | E8: ='Data Sheet'!D22 -> 1860 | F8: ='Data Sheet'!E22 -> 1875 | G8: ='Data Sheet'!F22 -> 1820 | H8: ='Data Sheet'!G22 -> 2358 | I8: ='Data Sheet'!H22 -> 2545 | J8: ='Data Sheet'!I22 -> 2854 | ... L8: ='Data Sheet'!K22 -> 3077
B9: Selling and Admin | C9: ='Data Sheet'!B23 -> 6741 | D9: ='Data Sheet'!C23 -> 6689 | E9: ='Data Sheet'!D23 -> 7252 | F9: ='Data Sheet'!E23 -> 7796 | G9: ='Data Sheet'!F23 -> 7620 | H9: ='Data Sheet'!G23 -> 7906 | I9: ='Data Sheet'!H23 -> 8164 | J9: ='Data Sheet'!I23 -> 8785 | ... L9: ='Data Sheet'!K23 -> 10693
B10: Depreciation | C10: ='Data Sheet'!B26 -> 353 | D10: ='Data Sheet'!C26 -> 432 | E10: ='Data Sheet'!D26 -> 520 | F10: ='Data Sheet'!E26 -> 565 | G10: ='Data Sheet'!F26 -> 1002 | H10: ='Data Sheet'!G26 -> 1074 | I10: ='Data Sheet'!H26 -> 1091 | J10: ='Data Sheet'!I26 -> 1137 | ... L10: ='Data Sheet'!K26 -> 1355
B11: Interest | C11: ='Data Sheet'!B27 -> 17 | D11: ='Data Sheet'!C27 -> 35 | E11: ='Data Sheet'!D27 -> 26 | F11: ='Data Sheet'!E27 -> 33 | G11: ='Data Sheet'!F27 -> 118 | H11: ='Data Sheet'!G27 -> 117 | I11: ='Data Sheet'!H27 -> 106 | J11: ='Data Sheet'!I27 -> 114 | ... L11: ='Data Sheet'!K27 -> 395
B12: Profit before tax | C12: ='Data Sheet'!B28 -> 6026 | D12: ='Data Sheet'!C28 -> 6467 | E12: ='Data Sheet'!D28 -> 7306 | F12: ='Data Sheet'!E28 -> 8604 | G12: ='Data Sheet'!F28 -> 9165 | H12: ='Data Sheet'!G28 -> 10605 | I12: ='Data Sheet'!H28 -> 11879 | J12: ='Data Sheet'!I28 -> 13344 | ... L12: ='Data Sheet'!K28 -> 14415
B13: Tax | C13: ='Data Sheet'!B29 -> 1875 | D13: ='Data Sheet'!C29 -> 1977 | E13: ='Data Sheet'!D29 -> 2079 | F13: ='Data Sheet'!E29 -> 2544 | G13: ='Data Sheet'!F29 -> 2409 | H13: ='Data Sheet'!G29 -> 2606 | I13: ='Data Sheet'!H29 -> 2987 | J13: ='Data Sheet'!I29 -> 3201 | ... L13: ='Data Sheet'!K29 -> 3744
B14: Net Profit | C14: ='Data Sheet'!B30 -> 4151 | D14: ='Data Sheet'!C30 -> 4476 | E14: ='Data Sheet'!D30 -> 5214 | F14: ='Data Sheet'!E30 -> 6054 | G14: ='Data Sheet'!F30 -> 6748 | H14: ='Data Sheet'!G30 -> 7995 | I14: ='Data Sheet'!H30 -> 8879 | J14: ='Data Sheet'!I30 -> 10120 | ... L14: ='Data Sheet'!K30 -> 10649
B16: SECTION 2 — YEAR-ON-YEAR GROWTH (%)
B17: Particulars | C17: FY16 | D17: FY17 | E17: FY18 | F17: FY19 | G17: FY20 | H17: FY21 | I17: FY22 | J17: FY23 | K17: FY24 | L17: FY25
B18: Sales Growth % | C18: — | D18: =HistoricalFS!D7 -> 0.030323743 | E18: =HistoricalFS!E7 -> 0.071859357 | F18: =HistoricalFS!F7 -> 0.10592207 | G18: =HistoricalFS!G7 -> 0.012032562 | H18: =HistoricalFS!H7 -> 0.18211296 | I18: =HistoricalFS!I7 -> 0.11520796 | J18: =HistoricalFS!J7 -> 0.15509286 | K18: =HistoricalFS!K7 -> 0.021723341 | L18: =HistoricalFS!L7 -> 0.019791263
B19: Net Profit Growth % | C19: — | D19: =HistoricalFS!D33/HistoricalFS!C33-1 -> 0.07470651 | E19: =HistoricalFS!E33/HistoricalFS!D33-1 -> 0.19215492 | F19: =HistoricalFS!F33/HistoricalFS!E33-1 -> 0.19741774 | G19: =HistoricalFS!G33/HistoricalFS!F33-1 -> 0.082434783 | H19: =HistoricalFS!H33/HistoricalFS!G33-1 -> 0.19280206 | I19: =HistoricalFS!I33/HistoricalFS!H33-1 -> 0.16527478 | J19: =HistoricalFS!J33/HistoricalFS!I33-1 -> 0.11201017 | K19: =HistoricalFS!K33/HistoricalFS!J33-1 -> -0.017255717 | L19: =HistoricalFS!L33/HistoricalFS!K33-1 -> -0.027290036
B21: SECTION 3 — MARGIN ANALYSIS (% of Sales)
B22: Particulars | C22: FY16 | D22: FY17 | E22: FY18 | F22: FY19 | G22: FY20 | H22: FY21 | I22: FY22 | J22: FY23 | K22: FY24 | L22: FY25
B23: Gross Margin % | C23: =HistoricalFS!C13 -> 0.43643199 | D23: =HistoricalFS!D13 -> 0.44119776 | E23: =HistoricalFS!E13 -> 0.45460684 | F23: =HistoricalFS!F13 -> 0.46402951 | G23: =HistoricalFS!G13 -> 0.47912425 | H23: =HistoricalFS!H13 -> 0.45338947 | I23: =HistoricalFS!I13 -> 0.44537238 | J23: =HistoricalFS!J13 -> 0.41472433 | ... L23: =HistoricalFS!L13 -> 0.45054736
B24: Net Profit Margin % | C24: =HistoricalFS!C34 -> 0.11644815 | D24: =HistoricalFS!D34 -> 0.12146433 | E24: =HistoricalFS!E34 -> 0.13509636 | F24: =HistoricalFS!F34 -> 0.14627321 | G24: =HistoricalFS!G34 -> 0.15644873 | H24: =HistoricalFS!H34 -> 0.1578634 | I24: =HistoricalFS!I34 -> 0.16495062 | J24: =HistoricalFS!J34 -> 0.15879828 | ... L24: =HistoricalFS!L34 -> 0.14568844
